Workbook

Sheet 견적서
A1: N M S O L U T I O N | H1: 견적일자 | I1: 2026-10-19
A2: 견 적 서 | H2: 견적번호 | I2: NM-2610-01
A5: 수신 | F5: 공급자
A6: 업체명 | B6: 주식회사 금강변압기 | F6: 상호 | H6: 엔엠솔루션 (NM SOLUTION)
A7: 담당자 | F7: 대표 | H7: 김성배
A8: 연락처 | F8: 주소 | H8: 경기도 평택시 고덕동 도시지원로 121 지식공장아이타워 906호
A9: 현장 주소 | B9: 경기 화성시 마도면 마도공단로1길 214 (사내 마당) | F9: 전화 | H9: 대표 1800-5901 / 직통 010-2369-3691
A10: 공사명 | B10: 진공건조로 2분할체 회전·안착, 임시 베이스 제작, 접합부 사상·용접 공사 | F10: 홈페이지 | H10: nm-solution.co.kr
F11: 사업자등록번호
A13: 견적금액 일금 육천삼백육십삼만육천삼백육십사원정 (₩ 63,636,364, VAT 별도)
A15: 견적 내역
A16: 번호 | B16: 품명 | D16: 규격 | E16: 수량 | F16: 단위 | G16: 단가 | H16: 금액 | I16: 비고
B17: 도비 작업: 회전·베이스 안착, 밀착, 완성품 이동 (250t 1대), 안전펜스
A18: 1 | B18: 도비 전문기공 | D18: 회전·안착·밀착·완성품 이동 | E18: =도비!E8 -> 21 | F18: =도비!D8 -> 인·일 | G18: =도비!F8 -> 300000 | H18: =도비!G8 -> 6300000 | I18: 안착일 6명 + 밀착 6명·3명 + 이동일 6명 (6, 6, 3, 6)
A19: 2 | B19: 신호수 | D19: 크레인 인양 신호 | E19: =도비!E9 -> 4 | F19: =도비!D9 -> 인·일 | G19: =도비!F9 -> 260000 | H19: =도비!G9 -> 1040000 | I19: 2명 × 2일 (안착일 + 이동일)
A20: 3 | B20: 안전담당 (관리감독자) | D20: 작업 전 TBM·인양구역 통제 | E20: =도비!E10 -> 4 | F20: =도비!D10 -> 인·일 | G20: =도비!F10 -> 320000 | H20: =도비!G10 -> 1280000 | I20: 1명 × 4일
A21: 4 | B21: 크레인 | D21: 250TON | E21: =도비!E11 -> 2 | F21: =도비!D11 -> 대·일 | G21: =도비!F11 -> 5000000 | H21: =도비!G11 -> 10000000 | I21: 안착일 1일 + 이동일 1일
A22: 5 | B22: 아웃리거 받침 철판 | D22: 1,500×1,500×25t, 8매 | E22: =도비!E12 -> 1 | F22: =도비!D12 -> 식 | G22: =도비!F12 -> 640000 | H22: =도비!G12 -> 640000 | I22: 아스팔트 지반 보호
A23: 6 | B23: 밀착 장비 | D23: 유압잭·윈치·스키드 | E23: =도비!E13 -> 1 | F23: =도비!D13 -> SET | G23: =도비!F13 -> 2000000 | H23: =도비!G13 -> 2000000 | I23: 밀착 2일
A24: 7 | B24: 공구사용손료 | D24: 도비 전문장비·줄걸이구 | E24: =도비!E14 -> 1 | F24: =도비!D14 -> SET | G24: =도비!F14 -> 3000000 | H24: =도비!G14 -> 3000000
A25: 8 | B25: 소모품·잡자재 | D25: 목재 받침·와이어 보호대 등 | E25: =도비!E15 -> 1 | F25: =도비!D15 -> 식 | G25: =도비!F15 -> 1000000 | H25: =도비!G15 -> 1000000
A26: 9 | B26: 안전펜스 임대 | D26: 이동식 메쉬펜스 H1.8×W2.4m | E26: =도비!E16 -> 264 | F26: =도비!D16 -> 매·일 | G26: =도비!F16 -> 5000 | H26: =도비!G16 -> 1320000 | I26: 22매(둘레 50m + 출입문) × 12일
A27: 10 | B27: 펜스 설치·해체 | D27: 설치 인건비 | E27: =도비!E17 -> 2 | F27: =도비!D17 -> 인·일 | G27: =도비!F17 -> 250000 | H27: =도비!G17 -> 500000 | I27: 설치 2명 × 0.5일 + 해체 2명 × 0.5일
A28: 11 | B28: 펜스 운반 | D28: 1톤 화물 왕복 | E28: =도비!E18 -> 2 | F28: =도비!D18 -> 회 | G28: =도비!F18 -> 260000 | H28: =도비!G18 -> 520000 | I28: 반입 1 + 반출 1
A29: 12 | B29: 출입통제 안전장비 | E29: =도비!E19 -> 1 | F29: =도비!D19 -> 식 | G29: =도비!F19 -> 380000 | H29: =도비!G19 -> 380000
A30: 13 | B30: 경비 | D30: 간식·음료·교통비 등 | E30: =도비!E20 -> 1 | F30: =도비!D20 -> 식 | G30: =도비!F20 -> 600000 | H30: =도비!G20 -> 600000
A31: 14 | B31: 법정경비·일반관리비·이윤 | D31: 산재·고용보험, 산업안전보건관리비, 일반관리비, 이윤, 단수정리 | E31: 1 | F31: 식 | G31: =H31 -> 6636000 | H31: =도비!$G$31-도비!$G$21-도비!$G$22-도비!$G$23 -> 6636000 | I31: 원가계산서 참조
A32: 도비 소계 | H32: =도비!$G$31 -> 35216000 | I32: 도비 시트 참조
B33: 용접 작업: 접합면 사상, CO2 용접, 화재감시
A34: 15 | B34: 용접사 | D34: CO2 용접 (접합부) | E34: =용접!E8 -> 9 | F34: =용접!D8 -> 인·일 | G34: =용접!F8 -> 500000 | H34: =용접!G8 -> 4500000 | I34: 3명 × 3일
A35: 16 | B35: 고급기술자 | D35: 제관사 수준 (취부·치수 관리) | E35: =용접!E9 -> 6 | F35: =용접!D9 -> 인·일 | G35: =용접!F9 -> 350000 | H35: =용접!G9 -> 2100000 | I35: 2명 × 3일
A36: 17 | B36: 사상 기술자 | D36: 접합면 그라인딩 | E36: =용접!E10 -> 4 | F36: =용접!D10 -> 인·일 | G36: =용접!F10 -> 300000 | H36: =용접!G10 -> 1200000 | I36: 2명 × 2일
A37: 18 | B37: 조공 | D37: 사상·용접 보조 | E37: =용접!E11 -> 4 | F37: =용접!D11 -> 인·일 | G37: =용접!F11 -> 200000 | H37: =용접!G11 -> 800000 | I37: 2명 × 2일
A38: 19 | B38: 화재감시자 | D38: 용접·사상 화기작업 전담 | E38: =용접!E12 -> 5 | F38: =용접!D12 -> 인·일 | G38: =용접!F12 -> 250000 | H38: =용접!G12 -> 1250000 | I38: 1명 × 5일 (사상 2 + 용접 3)
A39: 20 | B39: CO2 용접기 대여 | D39: 500A급 | E39: =용접!E13 -> 9 | F39: =용접!D13 -> 대·일 | G39: =용접!F13 -> 400000 | H39: =용접!G13 -> 3600000 | I39: 3대 × 3일
A40: 21 | B40: 그라인더·환기·조명 | D40: 송풍기, 투광등 포함 | E40: =용접!E14 -> 1 | F40: =용접!D14 -> SET | G40: =용접!F14 -> 800000 | H40: =용접!G14 -> 800000
A41: 22 | B41: 용접 소모품 | D41: CO2 가스·와이어·디스크·케이블·잡자재 | E41: =용접!E15 -> 1 | F41: =용접!D15 -> 식 | G41: =용접!F15 -> 3680000 | H41: =용접!G15 -> 3680000
A42: 23 | B42: 작업발판 장비 임대 | E42: =용접!E16 -> 1 | F42: =용접!D16 -> 식 | G42: =용접!F16 -> 1000000 | H42: =용접!G16 -> 1000000
A43: 24 | B43: 가스절단기 임대 | D43: 산소·LPG, 2대 공정기간 상시 | E43: =용접!E17 -> 24 | F43: =용접!D17 -> 대·일 | G43: =용접!F17 -> 100000 | H43: =용접!G17 -> 2400000 | I43: 2대 × 12일
A44: 25 | B44: 경비 | D44: 식대·교통비·부대 잡비 | E44: =용접!E18 -> 1 | F44: =용접!D18 -> 식 | G44: =용접!F18 -> 1400000 | H44: =용접!G18 -> 1400000 | I44: 용접 9 + 고급기술자 6 + 사상 4 + 조공 4 + 화재감시 5
...

Sheet 원가계산서
A1: 공 사 원 가 계 산 서
A3: 공사명 : 진공건조로 회전·안착 및 접합부 용접 공사 | NM-2610-01
A5: 비목 | B5: 도비 | C5: 용접 | D5: 베이스 | E5: 합계 | F5: 구성비
A6: 재료비 | B6: =도비!$G$21 -> 1380000 | C6: =용접!$G$19 -> 3680000 | D6: =베이스!$G$11 -> 1800000 | E6: =SUM(B6:D6) -> 6860000 | F6: =E6/$E$16 -> 0.10364417
A7: 노무비 | B7: =도비!$G$22 -> 9120000 | C7: =용접!$G$20 -> 9850000 | D7: =베이스!$G$12 -> 1050000 | E7: =SUM(B7:D7) -> 20020000 | F7: =E7/$E$16 -> 0.30247175
A8: 경비 | B8: =도비!$G$23 -> 18080000 | C8: =용접!$G$21 -> 9200000 | D8: =베이스!$G$13 -> 160000 | E8: =SUM(B8:D8) -> 27440000 | F8: =E8/$E$16 -> 0.41457666
A9: 산재보험료 | B9: =도비!$G$24 -> 324672 | C9: =용접!$G$22 -> 350660 | D9: =베이스!$G$14 -> 0 | E9: =SUM(B9:D9) -> 675332 | F9: =E9/$E$16 -> 0.010203239
A10: 고용보험료 | B10: =도비!$G$25 -> 104880 | C10: =용접!$G$23 -> 113275 | D10: =베이스!$G$15 -> 0 | E10: =SUM(B10:D10) -> 218155 | F10: =E10/$E$16 -> 0.0032959902
A11: 산업안전보건관리비 | B11: =도비!$G$26 -> 326550 | C11: =용접!$G$24 -> 420783 | D11: =베이스!$G$16 -> 0 | E11: =SUM(B11:D11) -> 747333 | F11: =E11/$E$16 -> 0.011291065
A12: 순공사원가 | B12: =도비!$G$27 -> 29336102 | C12: =용접!$G$25 -> 23614718 | D12: =베이스!$G$17 -> 3010000 | E12: =SUM(B12:D12) -> 55960820 | F12: =E12/$E$16 -> 0.84548287
A13: 일반관리비 | B13: =도비!$G$28 -> 1466805.1 | C13: =용접!$G$26 -> 1180735.9 | D13: =베이스!$G$18 -> 0 | E13: =SUM(B13:D13) -> 2647541 | F13: =E13/$E$16 -> 0.040000317
A14: 이윤 | B14: =도비!$G$29 -> 4413436.1 | C14: =용접!$G$27 -> 3167318.1 | D14: =베이스!$G$19 -> 0 | E14: =SUM(B14:D14) -> 7580754.2 | F14: =E14/$E$16 -> 0.11453366
A15: 단수정리 | B15: =도비!$G$30 -> -343.165 | C15: =용접!$G$28 -> -771.985 | D15: =베이스!$G$20 -> 0 | E15: =SUM(B15:D15) -> -1115.15 | F15: =E15/$E$16 -> -1.684822e-05
A16: 공종 합계 | B16: =도비!$G$31 -> 35216000 | C16: =용접!$G$29 -> 27962000 | D16: =베이스!$G$21 -> 3010000 | E16: =SUM(B16:D16) -> 66188000 | F16: =E16/$E$16 -> 1
A17: 협의 조정 | E17: -2551636 | F17: 발주처 협의 금액 반영
A18: 공급가액 | E18: =E16+E17 -> 63636364
A19: 부가가치세 (10%) | E19: =ROUND(E18*0.1,0) -> 6363636
A20: 총 공사금액 | E20: =E18+E19 -> 70000000
A22: 요율: 산재 3.56%·고용 1.15% (노무비 기준), 산업안전보건관리비 3.11% ((재료비 + 노무비) 기준), 일반관리비 5% (순공사원가 기준), 이윤 15%. 근거는 아래 적용 요율 표. 베이스 공종은 회수조건 임시 구조물로 재료비·운반비·노무비만 계상함.
A24: 적용 요율
A25: 항목 | B25: 적용 기준 | D25: 요율 | E25: 근거
A26: 산재보험료 | B26: 노무비 × | D26: 0.0356 | E26: 2026년 고용노동부 보험료율 고시 (건설업)
A27: 고용보험료 | B27: 노무비 × | D27: 0.0115 | E27: 2026년 고용노동부 보험료율 고시 (150인 미만)
A28: 산업안전보건관리비 | B28: (재료비 + 노무비) × | D28: 0.0311 | E28: 고용노동부 산업안전보건관리비 계상기준
A29: 일반관리비 | B29: 순공사원가 × | D29: 0.05 | E29: 6% 이내 적용 (국가계약법 시행규칙 제8조 기준)
A30: 이윤 | B30: (노무비 + 경비 + 일반관리비) × | D30: 0.15 | E30: 15% 이내 적용 (국가계약법 시행규칙 제8조 기준)

Sheet 산출근거
A1: 견적 산출근거
A2: 금액은 공종 시트에서 연동됨. 인원·일수는 작업 범위와 공정표 기준, 단가는 동종 플랜트 현장 시장 단가 기준으로 산정함.
A4: 공종 | B4: 품명 | C4: 규격 | D4: 산출식 | E4: 금액(원) | F4: 근거
A5: 도비 | B5: 도비 전문기공 | C5: 회전·안착·밀착·완성품 이동 | D5: (6 + 6 + 3 + 6)명 × 300,000원 | E5: =도비!G8 -> 6300000 | F5: 인원·일수: 작업 범위·공정표 기준 / 단가: 중량물 도비 전문기공 시장 단가
A6: 도비 | B6: 신호수 | C6: 크레인 인양 신호 | D6: 2명 × 2일 × 260,000원 | E6: =도비!G9 -> 1040000 | F6: 크레인 인양 작업 안전관리 인력, 단가: 시장 단가
A7: 도비 | B7: 안전담당 (관리감독자) | C7: 작업 전 TBM·인양구역 통제 | D7: 1명 × 4일 × 320,000원 | E7: =도비!G10 -> 1280000 | F7: 크레인 인양 작업 안전관리 인력, 단가: 시장 단가
A8: 도비 | B8: 크레인 | C8: 250TON | D8: 1대 × 2일 × 5,000,000원 | E8: =도비!G11 -> 10000000 | F8: 이동식 크레인 1일 임대 시장 단가 (운전원 포함)
A9: 도비 | B9: 아웃리거 받침 철판 | C9: 1,500×1,500×25t, 8매 | D9: 8매 × 80,000원 | E9: =도비!G12 -> 640000 | F9: 장비 임대 시장 단가, 투입 수량·일수는 공정표 기준
A10: 도비 | B10: 밀착 장비 | C10: 유압잭·윈치·스키드 | D10: 1식 (2일) | E10: =도비!G13 -> 2000000 | F10: 장비 임대 시장 단가, 투입 수량·일수는 공정표 기준
A11: 도비 | B11: 공구사용손료 | C11: 도비 전문장비·줄걸이구 | D11: 1식 | E11: =도비!G14 -> 3000000 | F11: 중량물 작업 전문장비 사용 손료
A12: 도비 | B12: 소모품·잡자재 | C12: 목재 받침·와이어 보호대 등 | D12: 1식 | E12: =도비!G15 -> 1000000 | F12: 자재 시장 단가, 작업 범위 기준 1식
A13: 도비 | B13: 안전펜스 임대 | C13: 이동식 메쉬펜스 H1.8×W2.4m | D13: 작업구역 10×15m, 둘레 50m ÷ 2.4m = 21매 + 출입문 1매 → 22매 × 12일 × 5,000원 | E13: =도비!G16 -> 1320000 | F13: 작업구역 둘레 기준 수량 × 임대 시장 단가
A14: 도비 | B14: 펜스 설치·해체 | C14: 설치 인건비 | D14: 2명 × 1일 × 250,000원 | E14: =도비!G17 -> 500000 | F14: 인원·일수: 작업 범위·공정표 기준 / 단가: 플랜트 숙련 기능인력 시장 단가
A15: 도비 | B15: 펜스 운반 | C15: 1톤 화물 왕복 | D15: 2회 × 260,000원 | E15: =도비!G18 -> 520000 | F15: 화물 운반 시장 단가
A16: 도비 | B16: 출입통제 안전장비 | D16: 1식 | E16: =도비!G19 -> 380000 | F16: 작업구역 출입통제 자재, 1식
A17: 도비 | B17: 경비 | C17: 간식·음료·교통비 등 | D17: 1식 600,000원 | E17: =도비!G20 -> 600000 | F17: 공종 현장 부대비 1식
B18: 법정경비·일반관리비·이윤 | E18: =도비!$G$31-SUM(도비!$G$21:$G$23) -> 6636000 | F18: 법정 요율·일반관리비·이윤 (원가계산서 하단 참조)
B19: 공종 합계 | E19: =도비!$G$31 -> 35216000 | F19: 부가세 별도
A21: 용접 | B21: 용접사 | C21: CO2 용접 (접합부) | D21: 3명 × 3일 × 500,000원 | E21: =용접!G8 -> 4500000 | F21: 인원·일수: 작업 범위·공정표 기준 / 단가: 플랜트 숙련 기능인력 시장 단가
A22: 용접 | B22: 고급기술자 | C22: 제관사 수준 (취부·치수 관리) | D22: 2명 × 3일 × 350,000원 | E22: =용접!G9 -> 2100000 | F22: 인원·일수: 작업 범위·공정표 기준 / 단가: 플랜트 숙련 기능인력 시장 단가
A23: 용접 | B23: 사상 기술자 | C23: 접합면 그라인딩 | D23: 2명 × 2일 × 300,000원 | E23: =용접!G10 -> 1200000 | F23: 인원·일수: 작업 범위·공정표 기준 / 단가: 플랜트 숙련 기능인력 시장 단가
A24: 용접 | B24: 조공 | C24: 사상·용접 보조 | D24: 2명 × 2일 × 200,000원 | E24: =용접!G11 -> 800000 | F24: 인원·일수: 작업 범위·공정표 기준 / 단가: 플랜트 숙련 기능인력 시장 단가
A25: 용접 | B25: 화재감시자 | C25: 용접·사상 화기작업 전담 | D25: 1명 × 5일 × 250,000원 | E25: =용접!G12 -> 1250000 | F25: 산업안전보건기준에 관한 규칙 제241조의2 (화기작업 화재감시자 배치), 단가는 숙련 기능인력 시장 단가
A26: 용접 | B26: CO2 용접기 대여 | C26: 500A급 | D26: 3대 × 3일 × 400,000원 | E26: =용접!G13 -> 3600000 | F26: 장비 임대 시장 단가, 투입 수량·일수는 공정표 기준
A27: 용접 | B27: 그라인더·환기·조명 | C27: 송풍기, 투광등 포함 | D27: 1식 | E27: =용접!G14 -> 800000 | F27: 장비 임대 시장 단가, 투입 수량·일수는 공정표 기준
A28: 용접 | B28: 용접 소모품 | C28: CO2 가스·와이어·디스크·케이블·잡자재 | D28: 1식 (용접재 3,000,000 + 전원 케이블·잡자재 680,000) | E28: =용접!G15 -> 3680000 | F28: 자재 시장 단가, 작업 범위 기준 1식
A29: 용접 | B29: 작업발판 장비 임대 | D29: 1식 | E29: =용접!G16 -> 1000000 | F29: 장비 임대 시장 단가, 투입 수량·일수는 공정표 기준
A30: 용접 | B30: 가스절단기 임대 | C30: 산소·LPG, 2대 공정기간 상시 | D30: 2대 × 12일 × 100,000원 | E30: =용접!G17 -> 2400000 | F30: 장비 임대 시장 단가, 투입 수량·일수는 공정표 기준
A31: 용접 | B31: 경비 | C31: 식대·교통비·부대 잡비 | D31: 28인·일 기준 1식 | E31: =용접!G18 -> 1400000 | F31: 투입 인·일 기준 현장 부대비
B32: 법정경비·일반관리비·이윤 | E32: =용접!$G$29-SUM(용접!$G$19:$G$21) -> 5232000 | F32: 법정 요율·일반관리비·이윤 (원가계산서 하단 참조)
B33: 공종 합계 | E33: =용접!$G$29 -> 27962000 | F33: 부가세 별도
A35: 베이스 | B35: H빔 (회수조건) | C35: H-250×250×9×14, 10m 2EA·3m 2EA | D35: 1식 (1,882kg) | E35: =베이스!G8 -> 1800000 | F35: H빔 1,882kg (베이스자재 시트), 공사 후 회수 조건 1식
A36: 베이스 | B36: H빔 운반 | C36: 반입·회수 | D36: 1식 | E36: =베이스!G9 -> 160000 | F36: 화물 운반 시장 단가 (반입·회수)
A37: 베이스 | B37: 시공자 | C37: 베이스 배치·용접·회수 | D37: 3명 × 1일 × 350,000원 | E37: =베이스!G10 -> 1050000 | F37: 인원·일수: 작업 범위·공정표 기준 / 단가: 플랜트 숙련 기능인력 시장 단가
B38: 공종 합계 | E38: =베이스!$G$21 -> 3010000 | F38: 부가세 별도

Sheet 도비
A1: 공 종 별 내 역 서
A3: 견적번호 NM-2610-01 | 견적일 2026-10-19 | 주식회사 금강변압기 귀중
A5: 공 종 : 진공건조로 2기 회전·베이스 안착(1일), 용접면 밀착(2일), 완성품 이동(1일), 작업구역 안전펜스
A7: 구분 | B7: 품명 | C7: 규격 | D7: 단위 | E7: 수량 | F7: 단가 | G7: 금액 | H7: 비고 | I7: 비목
A8: 노무비 | B8: 도비 전문기공 | C8: 회전·안착·밀착·완성품 이동 | D8: 인·일 | E8: 21 | F8: 300000 | G8: =E8*F8 -> 6300000 | H8: 안착일 6명 + 밀착 6명·3명 + 이동일 6명 (6, 6, 3, 6) | I8: 노무비
B9: 신호수 | C9: 크레인 인양 신호 | D9: 인·일 | E9: 4 | F9: 260000 | G9: =E9*F9 -> 1040000 | H9: 2명 × 2일 (안착일 + 이동일) | I9: 노무비
B10: 안전담당 (관리감독자) | C10: 작업 전 TBM·인양구역 통제 | D10: 인·일 | E10: 4 | F10: 320000 | G10: =E10*F10 -> 1280000 | H10: 1명 × 4일 | I10: 노무비
A11: 장비 | B11: 크레인 | C11: 250TON | D11: 대·일 | E11: 2 | F11: 5000000 | G11: =E11*F11 -> 10000000 | H11: 안착일 1일 + 이동일 1일 | I11: 경비
B12: 아웃리거 받침 철판 | C12: 1,500×1,500×25t, 8매 | D12: 식 | E12: 1 | F12: 640000 | G12: =E12*F12 -> 640000 | H12: 아스팔트 지반 보호 | I12: 경비
B13: 밀착 장비 | C13: 유압잭·윈치·스키드 | D13: SET | E13: 1 | F13: 2000000 | G13: =E13*F13 -> 2000000 | H13: 밀착 2일 | I13: 경비
B14: 공구사용손료 | C14: 도비 전문장비·줄걸이구 | D14: SET | E14: 1 | F14: 3000000 | G14: =E14*F14 -> 3000000 | I14: 경비
A15: 재료비 | B15: 소모품·잡자재 | C15: 목재 받침·와이어 보호대 등 | D15: 식 | E15: 1 | F15: 1000000 | G15: =E15*F15 -> 1000000 | I15: 재료비
A16: 안전시설 | B16: 안전펜스 임대 | C16: 이동식 메쉬펜스 H1.8×W2.4m | D16: 매·일 | E16: 264 | F16: 5000 | G16: =E16*F16 -> 1320000 | H16: 22매(둘레 50m + 출입문) × 12일 | I16: 경비
B17: 펜스 설치·해체 | C17: 설치 인건비 | D17: 인·일 | E17: 2 | F17: 250000 | G17: =E17*F17 -> 500000 | H17: 설치 2명 × 0.5일 + 해체 2명 × 0.5일 | I17: 노무비
B18: 펜스 운반 | C18: 1톤 화물 왕복 | D18: 회 | E18: 2 | F18: 260000 | G18: =E18*F18 -> 520000 | H18: 반입 1 + 반출 1 | I18: 경비
B19: 출입통제 안전장비 | D19: 식 | E19: 1 | F19: 380000 | G19: =E19*F19 -> 380000 | I19: 재료비
A20: 경비 | B20: 경비 | C20: 간식·음료·교통비 등 | D20: 식 | E20: 1 | F20: 600000 | G20: =E20*F20 -> 600000 | I20: 경비
A21: 재료비 계 | G21: =SUMIF($I$8:$I$20,"재료비",$G$8:$G$20) -> 1380000
A22: 노무비 계 | G22: =SUMIF($I$8:$I$20,"노무비",$G$8:$G$20) -> 9120000
A23: 경비 계 | G23: =SUMIF($I$8:$I$20,"경비",$G$8:$G$20) -> 18080000
A24: 산재보험료 | G24: =G22*원가계산서!$D$26 -> 324672 | H24: 노무비 × 3.56%
A25: 고용보험료 | G25: =G22*원가계산서!$D$27 -> 104880 | H25: 노무비 × 1.15%
A26: 산업안전보건관리비 | G26: =(G21+G22)*원가계산서!$D$28 -> 326550 | H26: (재료비 + 노무비) × 3.11%
A27: 순공사원가 | G27: =SUM(G21:G26) -> 29336102
A28: 일반관리비 | G28: =G27*원가계산서!$D$29 -> 1466805.1 | H28: 순공사원가 × 5%
A29: 이윤 | G29: =(G22+G23+G24+G25+G26+G28)*원가계산서!$D$30 -> 4413436.1 | H29: (노무비 + 경비 + 일반관리비) × 15.0%
A30: 단수정리 | G30: =-MOD(G27+G28+G29,1000) -> -343.165 | H30: 천원 미만 절사
A31: 공종 합계 | G31: =G27+G28+G29+G30 -> 35216000 | H31: 부가세 별도
A33: ※ 수량·단가의 근거는 '산출근거' 시트에 정리함.
A34: ※ 연장·야간·휴일 작업은 공정에 따라 당사가 수행함 (추가 정산 없음).

Sheet 용접
A1: 공 종 별 내 역 서
A3: 견적번호 NM-2610-01 | 견적일 2026-10-19 | 주식회사 금강변압기 귀중
A5: 공 종 : 접합면 사상(2일) 및 접합부 CO2 용접(3일)
A7: 구분 | B7: 품명 | C7: 규격 | D7: 단위 | E7: 수량 | F7: 단가 | G7: 금액 | H7: 비고 | I7: 비목
A8: 노무비 | B8: 용접사 | C8: CO2 용접 (접합부) | D8: 인·일 | E8: 9 | F8: 500000 | G8: =E8*F8 -> 4500000 | H8: 3명 × 3일 | I8: 노무비
B9: 고급기술자 | C9: 제관사 수준 (취부·치수 관리) | D9: 인·일 | E9: 6 | F9: 350000 | G9: =E9*F9 -> 2100000 | H9: 2명 × 3일 | I9: 노무비
B10: 사상 기술자 | C10: 접합면 그라인딩 | D10: 인·일 | E10: 4 | F10: 300000 | G10: =E10*F10 -> 1200000 | H10: 2명 × 2일 | I10: 노무비
B11: 조공 | C11: 사상·용접 보조 | D11: 인·일 | E11: 4 | F11: 200000 | G11: =E11*F11 -> 800000 | H11: 2명 × 2일 | I11: 노무비
B12: 화재감시자 | C12: 용접·사상 화기작업 전담 | D12: 인·일 | E12: 5 | F12: 250000 | G12: =E12*F12 -> 1250000 | H12: 1명 × 5일 (사상 2 + 용접 3) | I12: 노무비
A13: 장비 | B13: CO2 용접기 대여 | C13: 500A급 | D13: 대·일 | E13: 9 | F13: 400000 | G13: =E13*F13 -> 3600000 | H13: 3대 × 3일 | I13: 경비
B14: 그라인더·환기·조명 | C14: 송풍기, 투광등 포함 | D14: SET | E14: 1 | F14: 800000 | G14: =E14*F14 -> 800000 | I14: 경비
A15: 재료비 | B15: 용접 소모품 | C15: CO2 가스·와이어·디스크·케이블·잡자재 | D15: 식 | E15: 1 | F15: 3680000 | G15: =E15*F15 -> 3680000 | I15: 재료비
A16: 장비 | B16: 작업발판 장비 임대 | D16: 식 | E16: 1 | F16: 1000000 | G16: =E16*F16 -> 1000000 | I16: 경비
B17: 가스절단기 임대 | C17: 산소·LPG, 2대 공정기간 상시 | D17: 대·일 | E17: 24 | F17: 100000 | G17: =E17*F17 -> 2400000 | H17: 2대 × 12일 | I17: 경비
A18: 경비 | B18: 경비 | C18: 식대·교통비·부대 잡비 | D18: 식 | E18: 1 | F18: 1400000 | G18: =E18*F18 -> 1400000 | H18: 용접 9 + 고급기술자 6 + 사상 4 + 조공 4 + 화재감시 5 | I18: 경비
A19: 재료비 계 | G19: =SUMIF($I$8:$I$18,"재료비",$G$8:$G$18) -> 3680000
A20: 노무비 계 | G20: =SUMIF($I$8:$I$18,"노무비",$G$8:$G$18) -> 9850000
A21: 경비 계 | G21: =SUMIF($I$8:$I$18,"경비",$G$8:$G$18) -> 9200000
A22: 산재보험료 | G22: =G20*원가계산서!$D$26 -> 350660 | H22: 노무비 × 3.56%
A23: 고용보험료 | G23: =G20*원가계산서!$D$27 -> 113275 | H23: 노무비 × 1.15%
A24: 산업안전보건관리비 | G24: =(G19+G20)*원가계산서!$D$28 -> 420783 | H24: (재료비 + 노무비) × 3.11%
A25: 순공사원가 | G25: =SUM(G19:G24) -> 23614718
A26: 일반관리비 | G26: =G25*원가계산서!$D$29 -> 1180735.9 | H26: 순공사원가 × 5%
A27: 이윤 | G27: =(G20+G21+G22+G23+G24+G26)*원가계산서!$D$30 -> 3167318.1 | H27: (노무비 + 경비 + 일반관리비) × 15.0%
A28: 단수정리 | G28: =-MOD(G25+G26+G27,1000) -> -771.985 | H28: 천원 미만 절사
A29: 공종 합계 | G29: =G25+G26+G27+G28 -> 27962000 | H29: 부가세 별도
A31: ※ 수량·단가의 근거는 '산출근거' 시트에 정리함.
A32: ※ 연장·야간·휴일 작업은 공정에 따라 당사가 수행함 (추가 정산 없음).

Sheet 베이스
A1: 공 종 별 내 역 서
A3: 견적번호 NM-2610-01 | 견적일 2026-10-19 | 주식회사 금강변압기 귀중
A5: 공 종 : 기존 철판 조방 위 H빔 임시 베이스 설치 및 공사 후 회수, H-250×250
A7: 구분 | B7: 품명 | C7: 규격 | D7: 단위 | E7: 수량 | F7: 단가 | G7: 금액 | H7: 비고 | I7: 비목
A8: 재료비 | B8: H빔 (회수조건) | C8: H-250×250×9×14, 10m 2EA·3m 2EA | D8: 식 | E8: 1 | F8: 1800000 | G8: =E8*F8 -> 1800000 | H8: 공사 후 회수 조건 | I8: 재료비
A9: 운반비 | B9: H빔 운반 | C9: 반입·회수 | D9: 식 | E9: 1 | F9: 160000 | G9: =E9*F9 -> 160000 | I9: 경비
A10: 노무비 | B10: 시공자 | C10: 베이스 배치·용접·회수 | D10: 인·일 | E10: 3 | F10: 350000 | G10: =E10*F10 -> 1050000 | H10: 3명 × 1일 | I10: 노무비
A11: 재료비 계 | G11: =SUMIF($I$8:$I$10,"재료비",$G$8:$G$10) -> 1800000
A12: 노무비 계 | G12: =SUMIF($I$8:$I$10,"노무비",$G$8:$G$10) -> 1050000
A13: 경비 계 | G13: =SUMIF($I$8:$I$10,"경비",$G$8:$G$10) -> 160000
A14: 산재보험료 | G14: =0 -> 0 | H14: 미적용
A15: 고용보험료 | G15: =0 -> 0 | H15: 미적용
A16: 산업안전보건관리비 | G16: =0 -> 0 | H16: 미적용
A17: 순공사원가 | G17: =SUM(G11:G16) -> 3010000
A18: 일반관리비 | G18: =0 -> 0 | H18: 미적용
A19: 이윤 | G19: =0 -> 0 | H19: 미적용
A20: 단수정리 | G20: =-MOD(G17+G18+G19,1000) -> 0 | H20: 천원 미만 절사
A21: 공종 합계 | G21: =G17+G18+G19+G20 -> 3010000 | H21: 부가세 별도
A23: ※ 수량·단가의 근거는 '산출근거' 시트에 정리함.
A24: ※ 연장·야간·휴일 작업은 공정에 따라 당사가 수행함 (추가 정산 없음).

Sheet 베이스자재
A1: 베이스 자재: H-250×250×9×14 (회수조건)
A3: 길이(m) | B3: 수량(EA) | C3: 총 길이(m) | D3: 단위중량(kg/m) | E3: 중량(kg)
A4: 10 | B4: 2 | C4: =A4*B4 -> 20 | D4: 72.4 | E4: =C4*D4 -> 1448
A5: 3 | B5: 2 | C5: =A5*B5 -> 6 | D5: 72.4 | E5: =C5*D5 -> 434.4
B6: 합계 | C6: =SUM(C4:C5) -> 26 | E6: =SUM(E4:E5) -> 1882.4
A9: 구분 | B9: 중량(kg) | C9: 수량 | D9: 금액(원) | E9: 비고
A10: H빔 (회수조건) | B10: =E6 -> 1882.4 | C10: 1식 | D10: =베이스!G8 -> 1800000 | E10: 공사 후 회수, 사용 기간 손료 개념
A12: 기존 철판 조방 위에 10m H빔 2본을 길이 방향으로 놓고, 양 끝에 3m H빔을 직각으로 용접함. 단위중량 72.4 kg/m는 KS H-250×250×9×14 공칭값. 임시 구조물로 방청·도장 미적용.

Sheet 공정표
A1: 공정표 (가정 일정 2026.10.21 ~ 11.03, 작업일 12일)
A3: 공정 | B3: 투입 인원 | C3: 10/21 수 | D3: 10/22 목 | E3: 10/23 금 | F3: 10/24 토 | G3: 10/26 월 | H3: 10/27 화 | I3: 10/28 수 | J3: 10/29 목 | K3: 10/30 금 | L3: 10/31 토 | M3: 11/2 월 | N3: 11/3 화
A4: 안전펜스 설치·작업구역 통제 | B4: 조공 2명
A5: 베이스 설치 (H빔 배치·용접) | B5: 시공자 3명
A6: 회전·베이스 안착 (250t) | B6: 도비 6명, 신호수 2, 안전담당
A7: 접합면 사상 | B7: 사상 2, 조공 2, 화재감시 1
A8: 용접면 밀착 | B8: 도비 6명·3명, 안전담당
A9: 접합부 용접 | B9: 용접사 3, 고급기술자 2, 화재감시 1
A10: 완성품 이동 (250t)·베이스 회수 | B10: 도비 6명, 신호수 2, 안전담당
A11: 펜스 해체·정리 | B11: 조공 2명
A13: 가정 일정: 2026-10-21(수) 착공 ~ 11-03(화) 완료, 일요일 휴무 기준 작업일 12일. 날짜는 가정이며 착공일은 발주처 협의로 확정함.
